Workbook
Name Afecta: [1]Maestro!$I$2:$I$3
Name Afecta: Maestro!$I$8:$I$9
Name Res_Falla: [1]Maestro!$H$2:$H$3
Name Res_Falla: Maestro!$H$8:$H$9
Name Tipo_Afect: [1]Maestro!$G$2:$G$3
Name Tipo_Afect: Maestro!$G$8:$G$9

Sheet BD indisponibilidad
C1: 8 | AA1: Código | AB1: FR-GDO-013
C2: FORMATO | AA2: Versión | AB2: 0
C3: BITÁCORA DISPONIBILIDAD DE PRODUCTOS | AA3: Fecha | AB3: 45525
H5: Aplicación Afectada | M5: Empresa(s) Afectada(s) | T5: Producto Afectada(s)
A6: Mes | B6: Producto afectado o aplicación | C6: Incidente | D6: Fecha y hora inicio | E6: Fecha y hora fin | F6: Tiempo falla (en Mintuos) | G6: Tipo de afectación | H6: JADE | I6: SIGA | J6: APLICACIONES WEB GANA | K6: INVICTUS | L6: SALO -LOTERIA | M6: Acertemos - Cauca | N6: Jer - Boyacá | O6: Suchance - Huila | P6: MatrixRedes | Q6: Gana - Antioquia | R6: Gana Gana - Tolima | S6: Santander La Perla | T6: Apuestas - Chance | U6: PAGOS | V6: RECAUDOS | W6: RECARGAS | X6: Responsable Falla | Y6: Descripción | Z6: Causa raiz | AA6: Plan accion | AB6: Analista MDS
A7: Enero | B7: JADE | C7: INC 2026-000722 | D7: 46024.542 | E7: 46024.558 | F7: 60 | G7: caÍda total | H7: SI | I7: NO | J7: NO | K7: SI | L7: NO | M7: NO | N7: NO | O7: NO | P7: NO | Q7: SI | R7: NO | S7: NO | T7: SI | U7: SI | V7: SI | W7: SI | X7: Matrix Tech | Y7: No deja ingresar | Z7: Contension en base de datos | AA7: Sevalida con el area de BD quein escala al proveedor | AB7: NICOLAS QUIROGA
A8: Enero | B8: CAIDA GENERAL JADE | C8: 728296 | D8: 46038.346 | E8: 46038.365 | F8: =+(disponibilidad[[#This Row],[Fecha y hora fin]]-disponibilidad[[#This Row],[Fecha y hora inicio]])*1440 -> 27 | G8: Intermitencia | H8: SI | I8: NO | J8: NO | K8: NO | L8: NO | M8: NO | N8: NO | O8: SI | P8: NO | Q8: NO | R8: NO | S8: NO | T8: SI | U8: SI | V8: SI | W8: SI | X8: Matrix Tech | Y8: intermitencia en el aplicativo | Z8: Res afectada | AA8: Se realiza un reinicio controlado en los servidores de la red para restablecer el servicio | AB8: JORGEN VALDES
A9: Enero | B9: Caida general JADE | C9: 728306 | D9: 46038.458 | E9: 46038.472 | F9: =+(disponibilidad[[#This Row],[Fecha y hora fin]]-disponibilidad[[#This Row],[Fecha y hora inicio]])*1440 -> 20 | G9: caÍda total | H9: SI | I9: NO | J9: NO | K9: NO | L9: NO | M9: NO | N9: NO | O9: NO | P9: NO | Q9: NO | R9: SI | S9: NO | T9: SI | U9: SI | V9: SI | W9: SI | X9: Matrix Tech | Y9: caida general del sistema | Z9: Afectacion el el servidor | AA9: Se realiza un reinicio controlado de los servidores, se restablece el servicio | AB9: JORGEN VALDES
A10: Enero | B10: NOVEDAD JADE - INTERMITENCIA Y/O LENTITUD APLICATIVO | C10: 728344 | D10: 46041.349 | E10: 46041.36 | F10: =+(disponibilidad[[#This Row],[Fecha y hora fin]]-disponibilidad[[#This Row],[Fecha y hora inicio]])*1440 -> 15 | G10: Intermitencia | H10: SI | I10: NO | J10: NO | K10: NO | L10: NO | M10: NO | N10: NO | O10: NO | P10: NO | Q10: NO | R10: NO | S10: SI | T10: SI | U10: SI | V10: SI | W10: SI | X10: Matrix Tech | Y10: intermitencia en el aplicativo | Z10: sw_default con afectacion | AA10: Se realiza un reinicio controlado en los servidores de la red para restablecer el servicio | AB10: JORGEN VALDES
A11: Enero | B11: CAIDA GENERAL DE SIGA Y JADE | C11: 728342 | D11: 46041.347 | E11: 46041.36 | F11: =+(disponibilidad[[#This Row],[Fecha y hora fin]]-disponibilidad[[#This Row],[Fecha y hora inicio]])*1440 -> 18 | G11: Intermitencia | H11: SI | I11: NO | J11: NO | K11: NO | L11: NO | M11: NO | N11: NO | O11: SI | P11: NO | Q11: NO | R11: NO | S11: NO | T11: SI | U11: SI | V11: SI | W11: SI | X11: Matrix Tech | Y11: intermitencia en el aplicativo | Z11: Res afectada | AA11: Se realiza un reinicio controlado en los servidores de la red para restablecer el servicio | AB11: JORGEN VALDES
A12: Enero | B12: Novedad Jade | C12: 728345 | D12: 46041.363 | E12: 46041.372 | F12: =+(disponibilidad[[#This Row],[Fecha y hora fin]]-disponibilidad[[#This Row],[Fecha y hora inicio]])*1440 -> 12 | G12: Intermitencia | H12: SI | I12: NO | J12: NO | K12: NO | L12: NO | M12: SI | N12: NO | O12: NO | P12: NO | Q12: NO | R12: NO | S12: NO | T12: SI | U12: SI | V12: SI | W12: SI | X12: Matrix Tech | Y12: intermitencia en el aplicativo | Z12: Res afectada | AA12: Se realiza un reinicio controlado de los servidores, se restablece el servicio | AB12: JORGEN VALDES
A13: Enero | B13: Novedad Jade | C13: 728381 | D13: 46042.313 | E13: 46042.321 | F13: =+(disponibilidad[[#This Row],[Fecha y hora fin]]-disponibilidad[[#This Row],[Fecha y hora inicio]])*1440 -> 11 | G13: Intermitencia | H13: SI | I13: NO | J13: NO | K13: NO | L13: NO | M13: SI | N13: NO | O13: NO | P13: NO | Q13: NO | R13: NO | S13: NO | T13: SI | U13: SI | V13: SI | W13: SI | X13: Matrix Tech | Y13: intermitencia en el aplicativo | Z13: Res afectada | AA13: Se realiza un reinicio controlado de los servidores, se restablece el servicio | AB13: JORGEN VALDES
A14: Enero | B14: Lentitud JADE | C14: 728382 | D14: 46042.314 | E14: 46042.33 | F14: =+(disponibilidad[[#This Row],[Fecha y hora fin]]-disponibilidad[[#This Row],[Fecha y hora inicio]])*1440 -> 23 | G14: Intermitencia | H14: SI | I14: NO | J14: NO | K14: NO | L14: NO | M14: NO | N14: NO | O14: SI | P14: NO | Q14: NO | R14: NO | S14: NO | T14: SI | U14: SI | V14: SI | W14: SI | X14: Matrix Tech | Y14: intermitencia en el aplicativo | Z14: Res afectada | AA14: Se realiza un reinicio controlado de los servidores, se restablece el servicio | AB14: JORGEN VALDES
A15: Enero | B15: NOVEDAD JADE - LENTITUD Y/O INTERMITENCIA JADE | C15: 728385 | D15: 46042.349 | E15: 46042.404 | F15: =+(disponibilidad[[#This Row],[Fecha y hora fin]]-disponibilidad[[#This Row],[Fecha y hora inicio]])*1440 -> 79 | G15: Intermitencia | H15: SI | I15: NO | J15: NO | K15: NO | L15: NO | M15: NO | N15: NO | O15: NO | P15: NO | Q15: NO | R15: NO | S15: SI | T15: SI | U15: SI | V15: SI | W15: SI | X15: Matrix Tech | Y15: intermitencia en el aplicativo | Z15: backup traslado de copias base de datos | AA15: Se finaliza de forma forzada el traslado de los backup de base de datos servicio se restablece. | AB15: JORGEN VALDES
A16: Enero | B16: recargas metro sin tx | C16: INC 2026-017677 | D16: 46044.387 | E16: 46044.438 | F16: =+(disponibilidad[[#This Row],[Fecha y hora fin]]-disponibilidad[[#This Row],[Fecha y hora inicio]])*1440 -> 72 | G16: caÍda total | H16: SI | I16: NO | J16: NO | K16: NO | L16: NO | M16: NO | N16: NO | O16: NO | P16: NO | Q16: SI | R16: NO | S16: NO | T16: NO | U16: NO | V16: SI | W16: NO | X16: Aliados o terceros | Y16: no se evidencian tx para el producto | Z16: Se identifica que la novedad correspondía a una incidencia general del aliado. | AA16: El aliado informó y gestionó la corrección de la incidencia. Actualmente el servicio se encuentra restablecido y las transacciones se están procesando con normalidad. | AB16: JORGEN VALDES
A17: Enero | B17: Lentitud JADE | C17: 728503 | D17: 46045.6 | E17: 46045.611 | F17: =+(disponibilidad[[#This Row],[Fecha y hora fin]]-disponibilidad[[#This Row],[Fecha y hora inicio]])*1440 -> 16 | G17: Intermitencia | H17: SI | I17: NO | J17: NO | K17: NO | L17: NO | M17: NO | N17: NO | O17: SI | P17: NO | Q17: NO | R17: NO | S17: NO | T17: SI | U17: SI | V17: SI | W17: SI | X17: Matrix Tech | Y17: intermitencia en el aplicativo | Z17: sw_default con afectacion | AA17: Se realiza un reinicio controlado de los servidores, se restablece el servicio | AB17: JORGEN VALDES
A18: Enero | B18: CAIDA GENERAL APLICATIVO JADE | C18: 728576 | D18: 46048.341 | E18: 46048.36 | F18: =+(disponibilidad[[#This Row],[Fecha y hora fin]]-disponibilidad[[#This Row],[Fecha y hora inicio]])*1440 -> 28 | G18: caÍda total | H18: SI | I18: NO | J18: NO | K18: NO | L18: NO | M18: NO | N18: NO | O18: SI | P18: NO | Q18: NO | R18: NO | S18: NO | T18: SI | U18: SI | V18: SI | W18: SI | X18: Matrix Tech | Y18: intermitencia en el aplicativo | Z18: sw_default con afectacion | AA18: Se realiza un reinicio controlado de los servidores, se restablece el servicio | AB18: JORGEN VALDES
A19: Enero | B19: CAIDA GENERAL EN JADE | C19: 728580 | D19: 46048.349 | E19: 46048.36 | F19: =+(disponibilidad[[#This Row],[Fecha y hora fin]]-disponibilidad[[#This Row],[Fecha y hora inicio]])*1440 -> 17 | G19: caÍda total | H19: SI | I19: NO | J19: NO | K19: NO | L19: NO | M19: NO | N19: SI | O19: NO | P19: NO | Q19: NO | R19: NO | S19: NO | T19: SI | U19: SI | V19: SI | W19: SI | X19: Matrix Tech | Y19: intermitencia en el aplicativo | Z19: sw_default con afectacion | AA19: Se realiza un reinicio controlado de los servidores, se restablece el servicio | AB19: JORGEN VALDES
A20: Enero | B20: CAIDA GENERAL CON JADE | C20: 728621 | D20: 46049.282 | E20: 46049.303 | F20: =+(disponibilidad[[#This Row],[Fecha y hora fin]]-disponibilidad[[#This Row],[Fecha y hora inicio]])*1440 -> 30 | G20: caÍda total | H20: SI | I20: NO | J20: NO | K20: NO | L20: NO | M20: NO | N20: SI | O20: NO | P20: NO | Q20: NO | R20: NO | S20: NO | T20: SI | U20: SI | V20: SI | W20: SI | X20: Matrix Tech | Y20: caida general del sistema | Z20: falla en la venta de mantenimiento BD | AA20: Se realiza rollback de proceso para no afectar mas los servicios, se valida con la red indicando normalidad | AB20: JORGEN VALDES
A21: Enero | B21: intermitencia JADE | C21: 728660 | D21: 46049.743 | E21: 46049.752 | F21: =+(disponibilidad[[#This Row],[Fecha y hora fin]]-disponibilidad[[#This Row],[Fecha y hora inicio]])*1440 -> 13 | G21: Intermitencia | H21: SI | I21: NO | J21: NO | K21: NO | L21: NO | M21: NO | N21: NO | O21: NO | P21: NO | Q21: NO | R21: SI | S21: NO | T21: SI | U21: SI | V21: SI | W21: SI | X21: Matrix Tech | Y21: intermitencia en el aplicativo | Z21: Res afectada | AA21: Se realiza un reinicio controlado de los servidores, se restablece el servicio | AB21: JORGEN VALDES
A22: Enero | B22: CAIDA GENERAL JADE | C22: 728682 | D22: 46050.515 | E22: 46050.524 | F22: =+(disponibilidad[[#This Row],[Fecha y hora fin]]-disponibilidad[[#This Row],[Fecha y hora inicio]])*1440 -> 13 | G22: caÍda total | H22: SI | I22: NO | J22: NO | K22: NO | L22: NO | M22: NO | N22: NO | O22: SI | P22: NO | Q22: NO | R22: NO | S22: NO | T22: SI | U22: SI | V22: SI | W22: SI | X22: Matrix Tech | Y22: intermitencia en el aplicativo | Z22: sw_default con afectacion | AA22: Se realiza un reinicio controlado de los servidores, se restablece el servicio | AB22: JORGEN VALDES
A23: Enero | B23: CAIDA GENERAL JADE | C23: 728759 | D23: 46052.345 | E23: 46052.357 | F23: =+(disponibilidad[[#This Row],[Fecha y hora fin]]-disponibilidad[[#This Row],[Fecha y hora inicio]])*1440 -> 17 | G23: caÍda total | H23: SI | I23: NO | J23: NO | K23: NO | L23: NO | M23: NO | N23: NO | O23: SI | P23: NO | Q23: NO | R23: NO | S23: NO | T23: SI | U23: SI | V23: SI | W23: SI | X23: Matrix Tech | Y23: intermitencia en el aplicativo | Z23: sw_default con afectacion | AA23: Se realiza un reinicio controlado de los servidores, se restablece el servicio | AB23: JORGEN VALDES
A24: Enero | B24: Error devolucion de loteria | C24: INC 2026-024889 | D24: 46052.661 | E24: 46052.701 | F24: =+(disponibilidad[[#This Row],[Fecha y hora fin]]-disponibilidad[[#This Row],[Fecha y hora inicio]])*1440 -> 58 | G24: caÍda total | H24: SI | I24: SI | J24: NO | K24: NO | L24: SI | M24: NO | N24: NO | O24: NO | P24: NO | Q24: SI | R24: NO | S24: NO | T24: NO | U24: NO | V24: SI | W24: NO | X24: Matrix Tech | Y24: afectacion de plataformas jade y siga para devolver loterias | Z24: Se identifica error de memoria en el servidor afectador el servicio. | AA24: Se realiza reinicio de la api afectada se procede a validar con la red quedando operativo el servicio | AB24: JORGEN VALDES
A25: Enero | B25: Falla GANA Web. | C25: INC 2026-025209 | D25: 46052.877 | E25: 46052.919 | F25: =+(disponibilidad[[#This Row],[Fecha y hora fin]]-disponibilidad[[#This Row],[Fecha y hora inicio]])*1440 -> 61 | G25: Intermitencia | H25: NO | I25: NO | J25: SI | K25: NO | L25: NO | M25: NO | N25: NO | O25: NO | P25: NO | Q25: SI | R25: NO | S25: NO | T25: SI | U25: NO | V25: NO | W25: NO | X25: Matrix Tech | Y25: intermitencia en el aplicativo | Z25: Se presenta lentitud para generar una compra en la web | AA25: Se realiza un reinicio controlado en el servidor brilliance estabilizando el servicio pruebas en las web quedando operativo. | AB25: JORGEN VALDES
A26: Enero | B26: Recargas y Paquetes TIGO | C26: REQ 2026-025478 | D26: 46053.488 | E26: 46053.535 | F26: =F32+(disponibilidad[[#This Row],[Fecha y hora fin]]-disponibilidad[[#This Row],[Fecha y hora inicio]])*1440 -> 85 | G26: caÍda total | H26: SI | I26: NO | J26: NO | K26: SI | L26: NO | M26: NO | N26: NO | O26: NO | P26: NO | Q26: SI | R26: NO | S26: NO | T26: NO | U26: NO | V26: NO | W26: SI | X26: Aliados o terceros | Y26: No se evidencian tx para el producto | Z26: Error al recibir respuesta por parte del aliado | AA26: Se documenta el caso adjuntando los logs del error, se devuelva a lred para su gestion con el aliado | AB26: JORGEN VALDES
A27: Febrero | B27: PAQUETES CLARO | C27: INC 2026-026131 | D27: 46055.286 | E27: 46055.289 | F27: =+(disponibilidad[[#This Row],[Fecha y hora fin]]-disponibilidad[[#This Row],[Fecha y hora inicio]])*1440 -> 4 | G27: caÍda total | H27: NO | I27: NO | J27: NO | K27: NO | L27: NO | M27: NO | N27: NO | O27: NO | P27: NO | Q27: SI | R27: NO | S27: NO | T27: NO | U27: NO | V27: NO | W27: SI | X27: Aliados o terceros | Y27: no se evidencian tx para el producto | Z27: No se evidencia ninguna afectación en la transmisión de TX | AA27: Se realizan validaciones a nivel de BD y Servidores donde se evidencia la transmisión de TX con total normalidad. | AB27: STEVEN PINTO
A28: Febrero | B28: CAIDA GENERAL CON JADE | C28: 728830 | D28: 46055.301 | E28: 46055.319 | F28: =+(disponibilidad[[#This Row],[Fecha y hora fin]]-disponibilidad[[#This Row],[Fecha y hora inicio]])*1440 -> 26 | G28: caÍda total | H28: SI | I28: NO | J28: NO | K28: NO | L28: NO | M28: NO | N28: SI | O28: NO | P28: NO | Q28: NO | R28: NO | S28: NO | T28: SI | U28: SI | V28: SI | W28: SI | X28: Matrix Tech | Y28: caida general del sistema | Z28: Afectacion en el enlace de comunicacion | AA28: Se realiza validacion por parte del area de telecomunicaciones, una vez solventada la red indica normalidad | AB28: JORGEN VALDES
A29: Febrero | B29: Caida general JADE | C29: 728832 | D29: 46055.337 | E29: 46055.368 | F29: =+(disponibilidad[[#This Row],[Fecha y hora fin]]-disponibilidad[[#This Row],[Fecha y hora inicio]])*1440 -> 45 | G29: caÍda total | H29: SI | I29: NO | J29: NO | K29: NO | L29: NO | M29: NO | N29: NO | O29: SI | P29: NO | Q29: NO | R29: NO | S29: NO | T29: SI | U29: SI | V29: SI | W29: SI | X29: Matrix Tech | Y29: caida general del sistema | Z29: Afectacion por backup en BD | AA29: Se escala novedad al area de BD para validar los BAckup que estan generando lentitud en el servicio, la cual queda solventada | AB29: JORGEN VALDES
A30: Febrero | B30: RECARGAS OPERADORES SIN TX | C30: INC 2026-030741 | D30: 46055.463 | E30: 46055.476 | F30: =+(disponibilidad[[#This Row],[Fecha y hora fin]]-disponibilidad[[#This Row],[Fecha y hora inicio]])*1440 -> 19 | G30: caÍda total | H30: NO | I30: NO | J30: NO | K30: NO | L30: NO | M30: NO | N30: NO | O30: NO | P30: NO | Q30: SI | R30: NO | S30: NO | T30: NO | U30: NO | V30: NO | W30: SI | X30: Aliados o terceros | Y30: NO se evidencian tx para el producto | Z30: Error al recibir respuesta por parte del aliado | AA30: Se documenta el caso adjuntando los logs del error, se devuelva a lred para su gestion con el aliado | AB30: JORGEN VALDES
A31: Febrero | B31: CAIDA GENERAL CON JADE | C31: 728874 | D31: 46055.591 | E31: 46055.633 | F31: =+(disponibilidad[[#This Row],[Fecha y hora fin]]-disponibilidad[[#This Row],[Fecha y hora inicio]])*1440 -> 60 | G31: caÍda total | H31: SI | I31: NO | J31: NO | K31: NO | L31: NO | M31: NO | N31: SI | O31: NO | P31: NO | Q31: NO | R31: NO | S31: NO | T31: SI | U31: SI | V31: SI | W31: SI | X31: Matrix Tech | Y31: caida general del sistema | Z31: Afectacion en el enlace de comunicacion | AA31: Se realiza validacion por parte del area de telecomunicaciones, una vez solventada la red indica normalidad | AB31: JORGEN VALDES
A32: Febrero | B32: VIRGIN Y WOM SIN TX | C32: INC 2026-028413 | D32: 46057.257 | E32: 46057.269 | F32: =+(disponibilidad[[#This Row],[Fecha y hora fin]]-disponibilidad[[#This Row],[Fecha y hora inicio]])*1440 -> 18 | G32: caÍda total | H32: NO | I32: NO | J32: NO | K32: NO | L32: NO | M32: NO | N32: NO | O32: NO | P32: NO | Q32: SI | R32: NO | S32: NO | T32: NO | U32: NO | V32: NO | W32: SI | X32: Aliados o terceros | Y32: No se evidencian tx para el producto | Z32: No se evidencia ninguna afectación en la transmisión de TX | AA32: Se realizan validaciones a nivel de BD y Servidores donde se evidencia la transmisión de TX con total normalidad. | AB32: OSCAR FARID NAIZZIR
A33: Febrero | B33: COLORLOTO SIN TX | C33: INC 2026-028703 | D33: 46057.442 | E33: 46057.447 | F33: =+(disponibilidad[[#This Row],[Fecha y hora fin]]-disponibilidad[[#This Row],[Fecha y hora inicio]])*1440 -> 6 | G33: caÍda total | H33: NO | I33: NO | J33: NO | K33: NO | L33: NO | M33: NO | N33: NO | O33: NO | P33: NO | Q33: SI | R33: NO | S33: NO | T33: SI | U33: NO | V33: NO | W33: NO | X33: Matrix Tech | Y33: No se evidencian tx para el producto | Z33: No se evidencia ninguna afectación en la transmisión de TX | AA33: Se realizan validaciones a nivel de BD y Servidores donde se evidencia la transmisión de TX con total normalidad. | AB33: OSCAR FARID NAIZZIR
A34: Febrero | B34: RECARGAS METRO | C34: INC 2026-035446 | D34: 46065.333 | E34: 46065.368 | F34: =+(disponibilidad[[#This Row],[Fecha y hora fin]]-disponibilidad[[#This Row],[Fecha y hora inicio]])*1440 -> 50 | G34: caÍda total | H34: NO | I34: NO | J34: NO | K34: NO | L34: NO | M34: NO | N34: NO | O34: NO | P34: NO | Q34: SI | R34: NO | S34: NO | T34: NO | U34: NO | V34: NO | W34: SI | X34: Aliados o terceros | Y34: No se evidencian tx para el producto | Z34: Enlace (VPN) caido por parte del aliado | AA34: Se documenta el caso adjuntando los logs del error, se devuelva a lred para su gestion con el aliado | AB34: NICOLAS QUIROGA
A35: Febrero | B35: RECARGAS METRO | C35: INC 2026-026709 | D35: 46055.56 | E35: 46055.569 | F35: =+(disponibilidad[[#This Row],[Fecha y hora fin]]-disponibilidad[[#This Row],[Fecha y hora inicio]])*1440 -> 12 | G35: caÍda total | H35: NO | I35: NO | J35: NO | K35: NO | L35: NO | M35: NO | N35: NO | O35: NO | P35: NO | Q35: SI | R35: NO | S35: NO | T35: NO | U35: NO | V35: SI | W35: NO | X35: Aliados o terceros | Y35: no se evidencian tx para el producto | Z35: No se evidencia ninguna afectación en la transmisión de TX | AA35: Se realizan validaciones a nivel de BD y Servidores donde se evidencia la transmisión de TX con total normalidad. | AB35: STEVEN PINTO
A36: Febrero | B36: Recargas y Paquetes TIGO | C36: INC 2026-027219 | D36: 46056.257 | E36: 46056.269 | F36: =+(disponibilidad[[#This Row],[Fecha y hora fin]]-disponibilidad[[#This Row],[Fecha y hora inicio]])*1440 -> 17 | G36: caÍda total | H36: NO | I36: NO | J36: NO | K36: NO | L36: NO | M36: NO | N36: NO | O36: NO | P36: NO | Q36: SI | R36: NO | S36: NO | T36: NO | U36: NO | V36: NO | W36: SI | X36: Aliados o terceros | Y36: no se evidencian tx para el producto | Z36: No se evidencia ninguna afectación en la transmisión de TX | AA36: Se realizan validaciones a nivel de BD y Servidores donde se evidencia la transmisión de TX con total normalidad. | AB36: STEVEN PINTO
A37: Febrero | B37: RECAUDO EPM SIN TX | C37: INC 2026-027220 | D37: 46056.256 | E37: 46056.269 | F37: =+(disponibilidad[[#This Row],[Fecha y hora fin]]-disponibilidad[[#This Row],[Fecha y hora inicio]])*1440 -> 19 | G37: caÍda total | H37: NO | I37: NO | J37: NO | K37: NO | L37: NO | M37: NO | N37: NO | O37: NO | P37: NO | Q37: SI | R37: NO | S37: NO | T37: NO | U37: NO | V37: SI | W37: NO | X37: Aliados o terceros | Y37: no se evidencian tx para el producto | Z37: No se evidencia ninguna afectación en la transmisión de TX | AA37: Se realizan validaciones a nivel de BD y Servidores donde se evidencia la transmisión de TX con total normalidad. | AB37: STEVEN PINTO
A38: Febrero | B38: Baloto, mi loto y raspa y listo sin tx | C38: REQ 2026-027222 | D38: 46056.256 | E38: 46056.268 | F38: =+(disponibilidad[[#This Row],[Fecha y hora fin]]-disponibilidad[[#This Row],[Fecha y hora inicio]])*1440 -> 17 | G38: caÍda total | H38: NO | I38: NO | J38: NO | K38: NO | L38: NO | M38: NO | N38: NO | O38: NO | P38: NO | Q38: SI | R38: NO | S38: NO | T38: SI | U38: NO | V38: NO | W38: NO | X38: Aliados o terceros | Y38: no se evidencian tx para el producto | Z38: No se evidencia ninguna afectación en la transmisión de TX | AA38: Se realizan validaciones a nivel de BD y Servidores donde se evidencia la transmisión de TX con total normalidad. | AB38: STEVEN PINTO
A39: Febrero | B39: RECARGAS METRO | C39: INC 2026-026505 | D39: 46055.475 | E39: 46055.569 | F39: =+(disponibilidad[[#This Row],[Fecha y hora fin]]-disponibilidad[[#This Row],[Fecha y hora inicio]])*1440 -> 135 | G39: Intermitencia | H39: NO | I39: NO | J39: NO | K39: NO | L39: NO | M39: NO | N39: NO | O39: NO | P39: NO | Q39: SI | R39: NO | S39: NO | T39: NO | U39: NO | V39: SI | W39: NO | X39: Aliados o terceros | Y39: no se evidencian tx para el producto | Z39: No se evidencia ninguna afectación en la transmisión de TX | AA39: Se realizan validaciones a nivel de BD y Servidores donde se evidencia la transmisión de TX con total normalidad. | AB39: STEVEN PINTO
A40: Febrero | B40: operadores wom y virgin sin tx | C40: INC 2026-028413 | D40: 46057.258 | E40: 46057.269 | F40: =+(disponibilidad[[#This Row],[Fecha y hora fin]]-disponibilidad[[#This Row],[Fecha y hora inicio]])*1440 -> 17 | G40: caÍda total | H40: NO | I40: NO | J40: NO | K40: NO | L40: NO | M40: NO | N40: NO | O40: NO | P40: NO | Q40: SI | R40: NO | S40: NO | T40: NO | U40: NO | V40: NO | W40: SI | X40: Aliados o terceros | Y40: no se evidencian tx para el producto | Z40: No se evidencia ninguna afectación en la transmisión de TX | AA40: Se realizan validaciones a nivel de BD y Servidores donde se evidencia la transmisión de TX con total normalidad. | AB40: STEVEN PINTO
A41: Febrero | B41: COLORLOTO SIN TX | C41: INC 2026-028703 | D41: 46057.442 | E41: 46057.449 | F41: =+(disponibilidad[[#This Row],[Fecha y hora fin]]-disponibilidad[[#This Row],[Fecha y hora inicio]])*1440 -> 10 | G41: caÍda total | H41: NO | I41: NO | J41: NO | K41: NO | L41: NO | M41: NO | N41: NO | O41: NO | P41: NO | Q41: SI | R41: NO | S41: NO | T41: SI | U41: NO | V41: NO | W41: NO | X41: Matrix Tech | Y41: No se evidencian tx para el producto | Z41: No se evidencia ninguna afectación en la transmisión de TX | AA41: Se realizan validaciones a nivel de BD y Servidores donde se evidencia la transmisión de TX con total normalidad. | AB41: STEVEN PINTO
...

Sheet SuChance - Huila
E1: SGSI | L1: Código | N1: FR-GDO-013
E2: FORMATO | L2: Versión | N2: 0
E3: BITÁCORA DISPONIBILIDAD DE PRODUCTOS | L3: Fecha | N3: 45525
B5: Mes | C5: Minutos Mes | D5: Disponibilidad Individual Aplicación Matrix Tech | F5: Disponibilidad General Aplicación | G5: Disponibilidad Indivudual Producto UX TECHNOLOGY | K5: Disponibilidad General Producto | L5: Disponibilidad Indivudual Producto Aliados o Terceros | O5: Disponibilidad General Producto | P5: UX TECHNOLOGY | R5: Aliados - Terceros
D6: JADE | E6: SIGA | G6: Apuestas - Chance | H6: PAGOS | I6: RECAUDOS | J6: RECARGAS | L6: PAGOS | M6: RECAUDOS | N6: RECARGAS | P6: Tiempo Indisponibiliad | Q6: % Indisponibiliad | R6: Tiempo Indisponibiliad | S6: % Indisponibiliad
C7: AST/Peso | D7: 0.97 | E7: 0.03 | G7: 0.57 | H7: 0.03 | I7: 0.1 | J7: 0.3 | K7: =SUM(G7:J7) -> 1 | X7: MES | Y7: Mayo
B8: Enero | C8: =VLOOKUP(B8,Maestro!$A$7:$D$19,4,FALSE) -> 44640 | D8: =+(($C8-(SUMIFS(disponibilidad[Tiempo falla (en Mintuos)],disponibilidad[JADE],"SI",disponibilidad[Mes],$B8,disponibilidad[[Tipo de afectación ]],"caÍda total",disponibilidad[Responsable Falla],"Matrix Tech",disponibilidad[Suchance - Huila],"SI")))/$C8)*100 -> 99.870072 | E8: =+(($C8-(SUMIFS(disponibilidad[Tiempo falla (en Mintuos)],disponibilidad[SIGA],"SI",disponibilidad[Mes],$B8,disponibilidad[[Tipo de afectación ]],"caÍda total",disponibilidad[Responsable Falla],"Matrix Tech",disponibilidad[Suchance - Huila],"SI")))/$C8)*100 -> 100 | F8: =SUMPRODUCT($D$7:$E$7,D8:E8)/$K$7 -> 99.87397 | G8: =+(($C8-(SUMIFS(disponibilidad[Tiempo falla (en Mintuos)],disponibilidad[Apuestas - Chance],"SI",disponibilidad[Mes],$B8,disponibilidad[[Tipo de afectación ]],"caÍda total",disponibilidad[Responsable Falla],"Matrix Tech",disponibilidad[Suchance - Huila],"SI")))/$C8)*100 -> 99.870072 | H8: =+(($C8-(SUMIFS(disponibilidad[Tiempo falla (en Mintuos)],disponibilidad[PAGOS],"SI",disponibilidad[Mes],$B8,disponibilidad[[Tipo de afectación ]],"caÍda total",disponibilidad[Responsable Falla],"Matrix Tech",disponibilidad[Suchance - Huila],"SI")))/$C8)*100 -> 99.870072 | I8: =+(($C8-(SUMIFS(disponibilidad[Tiempo falla (en Mintuos)],disponibilidad[RECAUDOS],"SI",disponibilidad[Mes],$B8,disponibilidad[[Tipo de afectación ]],"caÍda total",disponibilidad[Responsable Falla],"Matrix Tech",disponibilidad[Suchance - Huila],"SI")))/$C8)*100 -> 99.870072 | J8: =+(($C8-(SUMIFS(disponibilidad[Tiempo falla (en Mintuos)],disponibilidad[RECARGAS],"SI",disponibilidad[Mes],$B8,disponibilidad[[Tipo de afectación ]],"caÍda total",disponibilidad[Responsable Falla],"Matrix Tech",disponibilidad[Suchance - Huila],"SI")))/$C8)*100 -> 99.870072 | K8: =SUMPRODUCT($G$7:$J$7,G8:J8)/$K$7 -> 99.870072 | L8: =+(($C8-(SUMIFS(disponibilidad[Tiempo falla (en Mintuos)],disponibilidad[PAGOS],"SI",disponibilidad[Mes],$B8,disponibilidad[[Tipo de afectación ]],"caÍda total",disponibilidad[Responsable Falla],"Aliados o terceros",disponibilidad[Suchance - Huila],"SI")))/$C8)*100 -> 100 | M8: =+(($C8-(SUMIFS(disponibilidad[Tiempo falla (en Mintuos)],disponibilidad[RECAUDOS],"SI",disponibilidad[Mes],$B8,disponibilidad[[Tipo de afectación ]],"caÍda total",disponibilidad[Responsable Falla],"Aliados o terceros",disponibilidad[Suchance - Huila],"SI")))/$C8)*100 -> 100 | N8: =+(($C8-(SUMIFS(disponibilidad[Tiempo falla (en Mintuos)],disponibilidad[RECARGAS],"SI",disponibilidad[Mes],$B8,disponibilidad[[Tipo de afectación ]],"caÍda total",disponibilidad[Responsable Falla],"Aliados o terceros",disponibilidad[Suchance - Huila],"SI")))/$C8)*100 -> 100 | O8: =AVERAGE(L8:N8) -> 100 | P8: =SUMIFS(disponibilidad[Tiempo falla (en Mintuos)],disponibilidad[Mes],$B8,disponibilidad[[Tipo de afectación ]],"caÍda total",disponibilidad[Responsable Falla],"Matrix Tech",disponibilidad[Suchance - Huila],"SI") -> 58 | Q8: =+$P$8/$C$8 -> 0.0012992832 | R8: =SUMIFS(disponibilidad[Tiempo falla (en Mintuos)],disponibilidad[Mes],$B8,disponibilidad[[Tipo de afectación ]],"caÍda total",disponibilidad[Responsable Falla],"Aliados o terceros",disponibilidad[Acertemos - Cauca],"SI") -> 0 | S8: =+$R$8/$C$8 -> 0
B9: Febrero | C9: =VLOOKUP(B9,Maestro!$A$7:$D$19,4,FALSE) -> 41760 | D9: =+(($C9-(SUMIFS(disponibilidad[Tiempo falla (en Mintuos)],disponibilidad[JADE],"SI",disponibilidad[Mes],$B9,disponibilidad[[Tipo de afectación ]],"caÍda total",disponibilidad[Responsable Falla],"Matrix Tech",disponibilidad[Suchance - Huila],"SI")))/$C9)*100 -> 99.810824 | E9: =+(($C9-(SUMIFS(disponibilidad[Tiempo falla (en Mintuos)],disponibilidad[SIGA],"SI",disponibilidad[Mes],$B9,disponibilidad[[Tipo de afectación ]],"caÍda total",disponibilidad[Responsable Falla],"Matrix Tech",disponibilidad[Suchance - Huila],"SI")))/$C9)*100 -> 100 | F9: =SUMPRODUCT($D$7:$E$7,D9:E9)/$K$7 -> 99.816499 | G9: =+(($C9-(SUMIFS(disponibilidad[Tiempo falla (en Mintuos)],disponibilidad[Apuestas - Chance],"SI",disponibilidad[Mes],$B9,disponibilidad[[Tipo de afectación ]],"caÍda total",disponibilidad[Responsable Falla],"Matrix Tech",disponibilidad[Suchance - Huila],"SI")))/$C9)*100 -> 99.810824 | H9: =+(($C9-(SUMIFS(disponibilidad[Tiempo falla (en Mintuos)],disponibilidad[PAGOS],"SI",disponibilidad[Mes],$B9,disponibilidad[[Tipo de afectación ]],"caÍda total",disponibilidad[Responsable Falla],"Matrix Tech",disponibilidad[Suchance - Huila],"SI")))/$C9)*100 -> 99.810824 | I9: =+(($C9-(SUMIFS(disponibilidad[Tiempo falla (en Mintuos)],disponibilidad[RECAUDOS],"SI",disponibilidad[Mes],$B9,disponibilidad[[Tipo de afectación ]],"caÍda total",disponibilidad[Responsable Falla],"Matrix Tech",disponibilidad[Suchance - Huila],"SI")))/$C9)*100 -> 99.810824 | J9: =+(($C9-(SUMIFS(disponibilidad[Tiempo falla (en Mintuos)],disponibilidad[RECARGAS],"SI",disponibilidad[Mes],$B9,disponibilidad[[Tipo de afectación ]],"caÍda total",disponibilidad[Responsable Falla],"Matrix Tech",disponibilidad[Suchance - Huila],"SI")))/$C9)*100 -> 99.810824 | K9: =SUMPRODUCT($G$7:$J$7,G9:J9)/$K$7 -> 99.810824 | L9: =+(($C9-(SUMIFS(disponibilidad[Tiempo falla (en Mintuos)],disponibilidad[PAGOS],"SI",disponibilidad[Mes],$B9,disponibilidad[[Tipo de afectación ]],"caÍda total",disponibilidad[Responsable Falla],"Aliados o terceros",disponibilidad[Acertemos - Cauca],"SI")))/$C9)*100 -> 100 | M9: =+(($C9-(SUMIFS(disponibilidad[Tiempo falla (en Mintuos)],disponibilidad[RECAUDOS],"SI",disponibilidad[Mes],$B9,disponibilidad[[Tipo de afectación ]],"caÍda total",disponibilidad[Responsable Falla],"Aliados o terceros",disponibilidad[Acertemos - Cauca],"SI")))/$C9)*100 -> 100 | N9: =+(($C9-(SUMIFS(disponibilidad[Tiempo falla (en Mintuos)],disponibilidad[RECARGAS],"SI",disponibilidad[Mes],$B9,disponibilidad[[Tipo de afectación ]],"caÍda total",disponibilidad[Responsable Falla],"Aliados o terceros",disponibilidad[Acertemos - Cauca],"SI")))/$C9)*100 -> 100 | O9: =AVERAGE(L9:N9) -> 100 | P9: =SUMIFS(disponibilidad[Tiempo falla (en Mintuos)],disponibilidad[Mes],$B9,disponibilidad[[Tipo de afectación ]],"caÍda total",disponibilidad[Responsable Falla],"Matrix Tech",disponibilidad[Suchance - Huila],"SI") -> 79 | Q9: =+P9/C9 -> 0.0018917625 | R9: =SUMIFS(disponibilidad[Tiempo falla (en Mintuos)],disponibilidad[Mes],$B9,disponibilidad[[Tipo de afectación ]],"caÍda total",disponibilidad[Responsable Falla],"Aliados o terceros",disponibilidad[Acertemos - Cauca],"SI") -> 0 | S9: =+$R$8/$C$8 -> 0 | X9: JADE | Y9: =VLOOKUP($Y$7,$B$8:$R$17,3,FALSE) -> 100
B10: Marzo | C10: =VLOOKUP(B10,Maestro!$A$7:$D$19,4,FALSE) -> 44640 | D10: =+(($C10-(SUMIFS(disponibilidad[Tiempo falla (en Mintuos)],disponibilidad[JADE],"SI",disponibilidad[Mes],$B10,disponibilidad[[Tipo de afectación ]],"caÍda total",disponibilidad[Responsable Falla],"Matrix Tech",disponibilidad[Suchance - Huila],"SI")))/$C10)*100 -> 100 | E10: =+(($C10-(SUMIFS(disponibilidad[Tiempo falla (en Mintuos)],disponibilidad[SIGA],"SI",disponibilidad[Mes],$B10,disponibilidad[[Tipo de afectación ]],"caÍda total",disponibilidad[Responsable Falla],"Matrix Tech",disponibilidad[Suchance - Huila],"SI")))/$C10)*100 -> 100 | F10: =SUMPRODUCT($D$7:$E$7,D10:E10)/$K$7 -> 100 | G10: =+(($C10-(SUMIFS(disponibilidad[Tiempo falla (en Mintuos)],disponibilidad[Apuestas - Chance],"SI",disponibilidad[Mes],$B10,disponibilidad[[Tipo de afectación ]],"caÍda total",disponibilidad[Responsable Falla],"Matrix Tech",disponibilidad[Suchance - Huila],"SI")))/$C10)*100 -> 100 | H10: =+(($C10-(SUMIFS(disponibilidad[Tiempo falla (en Mintuos)],disponibilidad[PAGOS],"SI",disponibilidad[Mes],$B10,disponibilidad[[Tipo de afectación ]],"caÍda total",disponibilidad[Responsable Falla],"Matrix Tech",disponibilidad[Suchance - Huila],"SI")))/$C10)*100 -> 100 | I10: =+(($C10-(SUMIFS(disponibilidad[Tiempo falla (en Mintuos)],disponibilidad[RECAUDOS],"SI",disponibilidad[Mes],$B10,disponibilidad[[Tipo de afectación ]],"caÍda total",disponibilidad[Responsable Falla],"Matrix Tech",disponibilidad[Suchance - Huila],"SI")))/$C10)*100 -> 100 | J10: =+(($C10-(SUMIFS(disponibilidad[Tiempo falla (en Mintuos)],disponibilidad[RECARGAS],"SI",disponibilidad[Mes],$B10,disponibilidad[[Tipo de afectación ]],"caÍda total",disponibilidad[Responsable Falla],"Matrix Tech",disponibilidad[Suchance - Huila],"SI")))/$C10)*100 -> 100 | K10: =SUMPRODUCT($G$7:$J$7,G10:J10)/$K$7 -> 100 | L10: =+(($C10-(SUMIFS(disponibilidad[Tiempo falla (en Mintuos)],disponibilidad[PAGOS],"SI",disponibilidad[Mes],$B10,disponibilidad[[Tipo de afectación ]],"caÍda total",disponibilidad[Responsable Falla],"Aliados o terceros",disponibilidad[Acertemos - Cauca],"SI")))/$C10)*100 -> 100 | M10: =+(($C10-(SUMIFS(disponibilidad[Tiempo falla (en Mintuos)],disponibilidad[RECAUDOS],"SI",disponibilidad[Mes],$B10,disponibilidad[[Tipo de afectación ]],"caÍda total",disponibilidad[Responsable Falla],"Aliados o terceros",disponibilidad[Acertemos - Cauca],"SI")))/$C10)*100 -> 100 | N10: =+(($C10-(SUMIFS(disponibilidad[Tiempo falla (en Mintuos)],disponibilidad[RECARGAS],"SI",disponibilidad[Mes],$B10,disponibilidad[[Tipo de afectación ]],"caÍda total",disponibilidad[Responsable Falla],"Aliados o terceros",disponibilidad[Acertemos - Cauca],"SI")))/$C10)*100 -> 100 | O10: =AVERAGE(L10:N10) -> 100 | P10: =SUMIFS(disponibilidad[Tiempo falla (en Mintuos)],disponibilidad[Mes],$B10,disponibilidad[[Tipo de afectación ]],"caÍda total",disponibilidad[Responsable Falla],"Matrix Tech",disponibilidad[Suchance - Huila],"SI") -> 0 | Q10: =+P10/C10 -> 0 | R10: =SUMIFS(disponibilidad[Tiempo falla (en Mintuos)],disponibilidad[Mes],$B10,disponibilidad[[Tipo de afectación ]],"caÍda total",disponibilidad[Responsable Falla],"Aliados o terceros",disponibilidad[Acertemos - Cauca],"SI") -> 0 | S10: =+$R$8/$C$8 -> 0 | X10: SIGA | Y10: =VLOOKUP($Y$7,$B$8:$R$17,4,FALSE) -> 100
B11: Abril | C11: =VLOOKUP(B11,Maestro!$A$7:$D$19,4,FALSE) -> 43200 | D11: =+(($C11-(SUMIFS(disponibilidad[Tiempo falla (en Mintuos)],disponibilidad[JADE],"SI",disponibilidad[Mes],$B11,disponibilidad[[Tipo de afectación ]],"caÍda total",disponibilidad[Responsable Falla],"Matrix Tech",disponibilidad[Suchance - Huila],"SI")))/$C11)*100 -> 100 | E11: =+(($C11-(SUMIFS(disponibilidad[Tiempo falla (en Mintuos)],disponibilidad[SIGA],"SI",disponibilidad[Mes],$B11,disponibilidad[[Tipo de afectación ]],"caÍda total",disponibilidad[Responsable Falla],"Matrix Tech",disponibilidad[Suchance - Huila],"SI")))/$C11)*100 -> 100 | F11: =SUMPRODUCT($D$7:$E$7,D11:E11)/$K$7 -> 100 | G11: =+(($C11-(SUMIFS(disponibilidad[Tiempo falla (en Mintuos)],disponibilidad[Apuestas - Chance],"SI",disponibilidad[Mes],$B11,disponibilidad[[Tipo de afectación ]],"caÍda total",disponibilidad[Responsable Falla],"Matrix Tech",disponibilidad[Suchance - Huila],"SI")))/$C11)*100 -> 100 | H11: =+(($C11-(SUMIFS(disponibilidad[Tiempo falla (en Mintuos)],disponibilidad[PAGOS],"SI",disponibilidad[Mes],$B11,disponibilidad[[Tipo de afectación ]],"caÍda total",disponibilidad[Responsable Falla],"Matrix Tech",disponibilidad[Suchance - Huila],"SI")))/$C11)*100 -> 100 | I11: =+(($C11-(SUMIFS(disponibilidad[Tiempo falla (en Mintuos)],disponibilidad[RECAUDOS],"SI",disponibilidad[Mes],$B11,disponibilidad[[Tipo de afectación ]],"caÍda total",disponibilidad[Responsable Falla],"Matrix Tech",disponibilidad[Suchance - Huila],"SI")))/$C11)*100 -> 100 | J11: =+(($C11-(SUMIFS(disponibilidad[Tiempo falla (en Mintuos)],disponibilidad[RECARGAS],"SI",disponibilidad[Mes],$B11,disponibilidad[[Tipo de afectación ]],"caÍda total",disponibilidad[Responsable Falla],"Matrix Tech",disponibilidad[Suchance - Huila],"SI")))/$C11)*100 -> 100 | K11: =SUMPRODUCT($G$7:$J$7,G11:J11)/$K$7 -> 100 | L11: =+(($C11-(SUMIFS(disponibilidad[Tiempo falla (en Mintuos)],disponibilidad[PAGOS],"SI",disponibilidad[Mes],$B11,disponibilidad[[Tipo de afectación ]],"caÍda total",disponibilidad[Responsable Falla],"Aliados o terceros",disponibilidad[Acertemos - Cauca],"SI")))/$C11)*100 -> 100 | M11: =+(($C11-(SUMIFS(disponibilidad[Tiempo falla (en Mintuos)],disponibilidad[RECAUDOS],"SI",disponibilidad[Mes],$B11,disponibilidad[[Tipo de afectación ]],"caÍda total",disponibilidad[Responsable Falla],"Aliados o terceros",disponibilidad[Acertemos - Cauca],"SI")))/$C11)*100 -> 100 | N11: =+(($C11-(SUMIFS(disponibilidad[Tiempo falla (en Mintuos)],disponibilidad[RECARGAS],"SI",disponibilidad[Mes],$B11,disponibilidad[[Tipo de afectación ]],"caÍda total",disponibilidad[Responsable Falla],"Aliados o terceros",disponibilidad[Acertemos - Cauca],"SI")))/$C11)*100 -> 100 | O11: =AVERAGE(L11:N11) -> 100 | P11: =SUMIFS(disponibilidad[Tiempo falla (en Mintuos)],disponibilidad[Mes],$B11,disponibilidad[[Tipo de afectación ]],"caÍda total",disponibilidad[Responsable Falla],"Matrix Tech",disponibilidad[Suchance - Huila],"SI") -> 0 | Q11: =+P11/C11 -> 0 | R11: =SUMIFS(disponibilidad[Tiempo falla (en Mintuos)],disponibilidad[Mes],$B11,disponibilidad[[Tipo de afectación ]],"caÍda total",disponibilidad[Responsable Falla],"Aliados o terceros",disponibilidad[Acertemos - Cauca],"SI") -> 0 | S11: =+$R$8/$C$8 -> 0 | T11: =AVERAGE(F11,K11) -> 100 | X11: General Aplicacion. | Y11: =VLOOKUP($Y$7,$B$8:$R$17,7,FALSE) -> 100
B12: Mayo | C12: =VLOOKUP(B12,Maestro!$A$7:$D$19,4,FALSE) -> 44640 | D12: =+(($C12-(SUMIFS(disponibilidad[Tiempo falla (en Mintuos)],disponibilidad[JADE],"SI",disponibilidad[Mes],$B12,disponibilidad[[Tipo de afectación ]],"caÍda total",disponibilidad[Responsable Falla],"Matrix Tech",disponibilidad[Suchance - Huila],"SI")))/$C12)*100 -> 100 | E12: =+(($C12-(SUMIFS(disponibilidad[Tiempo falla (en Mintuos)],disponibilidad[SIGA],"SI",disponibilidad[Mes],$B12,disponibilidad[[Tipo de afectación ]],"caÍda total",disponibilidad[Responsable Falla],"Matrix Tech",disponibilidad[Suchance - Huila],"SI")))/$C12)*100 -> 100 | F12: =SUMPRODUCT($D$7:$E$7,D12:E12)/$K$7 -> 100 | G12: =+(($C12-(SUMIFS(disponibilidad[Tiempo falla (en Mintuos)],disponibilidad[Apuestas - Chance],"SI",disponibilidad[Mes],$B12,disponibilidad[[Tipo de afectación ]],"caÍda total",disponibilidad[Responsable Falla],"Matrix Tech",disponibilidad[Suchance - Huila],"SI")))/$C12)*100 -> 100 | H12: =+(($C12-(SUMIFS(disponibilidad[Tiempo falla (en Mintuos)],disponibilidad[PAGOS],"SI",disponibilidad[Mes],$B12,disponibilidad[[Tipo de afectación ]],"caÍda total",disponibilidad[Responsable Falla],"Matrix Tech",disponibilidad[Suchance - Huila],"SI")))/$C12)*100 -> 100 | I12: =+(($C12-(SUMIFS(disponibilidad[Tiempo falla (en Mintuos)],disponibilidad[RECAUDOS],"SI",disponibilidad[Mes],$B12,disponibilidad[[Tipo de afectación ]],"caÍda total",disponibilidad[Responsable Falla],"Matrix Tech",disponibilidad[Suchance - Huila],"SI")))/$C12)*100 -> 100 | J12: =+(($C12-(SUMIFS(disponibilidad[Tiempo falla (en Mintuos)],disponibilidad[RECARGAS],"SI",disponibilidad[Mes],$B12,disponibilidad[[Tipo de afectación ]],"caÍda total",disponibilidad[Responsable Falla],"Matrix Tech",disponibilidad[Suchance - Huila],"SI")))/$C12)*100 -> 100 | K12: =SUMPRODUCT($G$7:$J$7,G12:J12)/$K$7 -> 100 | L12: =+(($C12-(SUMIFS(disponibilidad[Tiempo falla (en Mintuos)],disponibilidad[PAGOS],"SI",disponibilidad[Mes],$B12,disponibilidad[[Tipo de afectación ]],"caÍda total",disponibilidad[Responsable Falla],"Aliados o terceros",disponibilidad[Acertemos - Cauca],"SI")))/$C12)*100 -> 100 | M12: =+(($C12-(SUMIFS(disponibilidad[Tiempo falla (en Mintuos)],disponibilidad[RECAUDOS],"SI",disponibilidad[Mes],$B12,disponibilidad[[Tipo de afectación ]],"caÍda total",disponibilidad[Responsable Falla],"Aliados o terceros",disponibilidad[Acertemos - Cauca],"SI")))/$C12)*100 -> 100 | N12: =+(($C12-(SUMIFS(disponibilidad[Tiempo falla (en Mintuos)],disponibilidad[RECARGAS],"SI",disponibilidad[Mes],$B12,disponibilidad[[Tipo de afectación ]],"caÍda total",disponibilidad[Responsable Falla],"Aliados o terceros",disponibilidad[Acertemos - Cauca],"SI")))/$C12)*100 -> 100 | O12: =AVERAGE(L12:N12) -> 100 | P12: =SUMIFS(disponibilidad[Tiempo falla (en Mintuos)],disponibilidad[Mes],$B12,disponibilidad[[Tipo de afectación ]],"caÍda total",disponibilidad[Responsable Falla],"Matrix Tech",disponibilidad[Suchance - Huila],"SI") -> 0 | Q12: =+P12/C12 -> 0 | R12: =SUMIFS(disponibilidad[Tiempo falla (en Mintuos)],disponibilidad[Mes],$B12,disponibilidad[[Tipo de afectación ]],"caÍda total",disponibilidad[Responsable Falla],"Aliados o terceros",disponibilidad[Acertemos - Cauca],"SI") -> 0 | S12: =+$R$8/$C$8 -> 0
B13: Junio | C13: =VLOOKUP(B13,Maestro!$A$7:$D$19,4,FALSE) -> 43200 | D13: =+(($C13-(SUMIFS(disponibilidad[Tiempo falla (en Mintuos)],disponibilidad[JADE],"SI",disponibilidad[Mes],$B13,disponibilidad[[Tipo de afectación ]],"caÍda total",disponibilidad[Responsable Falla],"Matrix Tech",disponibilidad[Suchance - Huila],"SI")))/$C13)*100 -> 100 | E13: =+(($C13-(SUMIFS(disponibilidad[Tiempo falla (en Mintuos)],disponibilidad[SIGA],"SI",disponibilidad[Mes],$B13,disponibilidad[[Tipo de afectación ]],"caÍda total",disponibilidad[Responsable Falla],"Matrix Tech",disponibilidad[Suchance - Huila],"SI")))/$C13)*100 -> 100 | F13: =SUMPRODUCT($D$7:$E$7,D13:E13)/$K$7 -> 100 | G13: =+(($C13-(SUMIFS(disponibilidad[Tiempo falla (en Mintuos)],disponibilidad[Apuestas - Chance],"SI",disponibilidad[Mes],$B13,disponibilidad[[Tipo de afectación ]],"caÍda total",disponibilidad[Responsable Falla],"Matrix Tech",disponibilidad[Suchance - Huila],"SI")))/$C13)*100 -> 100 | H13: =+(($C13-(SUMIFS(disponibilidad[Tiempo falla (en Mintuos)],disponibilidad[PAGOS],"SI",disponibilidad[Mes],$B13,disponibilidad[[Tipo de afectación ]],"caÍda total",disponibilidad[Responsable Falla],"Matrix Tech",disponibilidad[Suchance - Huila],"SI")))/$C13)*100 -> 100 | I13: =+(($C13-(SUMIFS(disponibilidad[Tiempo falla (en Mintuos)],disponibilidad[RECAUDOS],"SI",disponibilidad[Mes],$B13,disponibilidad[[Tipo de afectación ]],"caÍda total",disponibilidad[Responsable Falla],"Matrix Tech",disponibilidad[Suchance - Huila],"SI")))/$C13)*100 -> 100 | J13: =+(($C13-(SUMIFS(disponibilidad[Tiempo falla (en Mintuos)],disponibilidad[RECARGAS],"SI",disponibilidad[Mes],$B13,disponibilidad[[Tipo de afectación ]],"caÍda total",disponibilidad[Responsable Falla],"Matrix Tech",disponibilidad[Suchance - Huila],"SI")))/$C13)*100 -> 100 | K13: =SUMPRODUCT($G$7:$J$7,G13:J13)/$K$7 -> 100 | L13: =+(($C13-(SUMIFS(disponibilidad[Tiempo falla (en Mintuos)],disponibilidad[PAGOS],"SI",disponibilidad[Mes],$B13,disponibilidad[[Tipo de afectación ]],"caÍda total",disponibilidad[Responsable Falla],"Aliados o terceros",disponibilidad[Acertemos - Cauca],"SI")))/$C13)*100 -> 100 | M13: =+(($C13-(SUMIFS(disponibilidad[Tiempo falla (en Mintuos)],disponibilidad[RECAUDOS],"SI",disponibilidad[Mes],$B13,disponibilidad[[Tipo de afectación ]],"caÍda total",disponibilidad[Responsable Falla],"Aliados o terceros",disponibilidad[Acertemos - Cauca],"SI")))/$C13)*100 -> 100 | N13: =+(($C13-(SUMIFS(disponibilidad[Tiempo falla (en Mintuos)],disponibilidad[RECARGAS],"SI",disponibilidad[Mes],$B13,disponibilidad[[Tipo de afectación ]],"caÍda total",disponibilidad[Responsable Falla],"Aliados o terceros",disponibilidad[Acertemos - Cauca],"SI")))/$C13)*100 -> 100 | O13: =AVERAGE(L13:N13) -> 100 | P13: =SUMIFS(disponibilidad[Tiempo falla (en Mintuos)],disponibilidad[Mes],$B13,disponibilidad[[Tipo de afectación ]],"caÍda total",disponibilidad[Responsable Falla],"Matrix Tech",disponibilidad[Suchance - Huila],"SI") -> 0 | Q13: =+P13/C13 -> 0 | R13: =SUMIFS(disponibilidad[Tiempo falla (en Mintuos)],disponibilidad[Mes],$B13,disponibilidad[[Tipo de afectación ]],"caÍda total",disponibilidad[Responsable Falla],"Aliados o terceros",disponibilidad[Acertemos - Cauca],"SI") -> 0 | S13: =+$R$8/$C$8 -> 0
B14: Julio | C14: =VLOOKUP(B14,Maestro!$A$7:$D$19,4,FALSE) -> 44640 | D14: =+(($C14-(SUMIFS(disponibilidad[Tiempo falla (en Mintuos)],disponibilidad[JADE],"SI",disponibilidad[Mes],$B14,disponibilidad[[Tipo de afectación ]],"caÍda total",disponibilidad[Responsable Falla],"Matrix Tech",disponibilidad[Suchance - Huila],"SI")))/$C14)*100 -> 100 | E14: =+(($C14-(SUMIFS(disponibilidad[Tiempo falla (en Mintuos)],disponibilidad[SIGA],"SI",disponibilidad[Mes],$B14,disponibilidad[[Tipo de afectación ]],"caÍda total",disponibilidad[Responsable Falla],"Matrix Tech",disponibilidad[Suchance - Huila],"SI")))/$C14)*100 -> 100 | F14: =SUMPRODUCT($D$7:$E$7,D14:E14)/$K$7 -> 100 | G14: =+(($C14-(SUMIFS(disponibilidad[Tiempo falla (en Mintuos)],disponibilidad[Apuestas - Chance],"SI",disponibilidad[Mes],$B14,disponibilidad[[Tipo de afectación ]],"caÍda total",disponibilidad[Responsable Falla],"Matrix Tech",disponibilidad[Suchance - Huila],"SI")))/$C14)*100 -> 100 | H14: =+(($C14-(SUMIFS(disponibilidad[Tiempo falla (en Mintuos)],disponibilidad[PAGOS],"SI",disponibilidad[Mes],$B14,disponibilidad[[Tipo de afectación ]],"caÍda total",disponibilidad[Responsable Falla],"Matrix Tech",disponibilidad[Suchance - Huila],"SI")))/$C14)*100 -> 100 | I14: =+(($C14-(SUMIFS(disponibilidad[Tiempo falla (en Mintuos)],disponibilidad[RECAUDOS],"SI",disponibilidad[Mes],$B14,disponibilidad[[Tipo de afectación ]],"caÍda total",disponibilidad[Responsable Falla],"Matrix Tech",disponibilidad[Suchance - Huila],"SI")))/$C14)*100 -> 100 | J14: =+(($C14-(SUMIFS(disponibilidad[Tiempo falla (en Mintuos)],disponibilidad[RECARGAS],"SI",disponibilidad[Mes],$B14,disponibilidad[[Tipo de afectación ]],"caÍda total",disponibilidad[Responsable Falla],"Matrix Tech",disponibilidad[Suchance - Huila],"SI")))/$C14)*100 -> 100 | K14: =SUMPRODUCT($G$7:$J$7,G14:J14)/$K$7 -> 100 | L14: =+(($C14-(SUMIFS(disponibilidad[Tiempo falla (en Mintuos)],disponibilidad[PAGOS],"SI",disponibilidad[Mes],$B14,disponibilidad[[Tipo de afectación ]],"caÍda total",disponibilidad[Responsable Falla],"Aliados o terceros",disponibilidad[Acertemos - Cauca],"SI")))/$C14)*100 -> 100 | M14: =+(($C14-(SUMIFS(disponibilidad[Tiempo falla (en Mintuos)],disponibilidad[RECAUDOS],"SI",disponibilidad[Mes],$B14,disponibilidad[[Tipo de afectación ]],"caÍda total",disponibilidad[Responsable Falla],"Aliados o terceros",disponibilidad[Acertemos - Cauca],"SI")))/$C14)*100 -> 100 | N14: =+(($C14-(SUMIFS(disponibilidad[Tiempo falla (en Mintuos)],disponibilidad[RECARGAS],"SI",disponibilidad[Mes],$B14,disponibilidad[[Tipo de afectación ]],"caÍda total",disponibilidad[Responsable Falla],"Aliados o terceros",disponibilidad[Acertemos - Cauca],"SI")))/$C14)*100 -> 100 | O14: =AVERAGE(L14:N14) -> 100 | P14: =SUMIFS(disponibilidad[Tiempo falla (en Mintuos)],disponibilidad[Mes],$B14,disponibilidad[[Tipo de afectación ]],"caÍda total",disponibilidad[Responsable Falla],"Matrix Tech",disponibilidad[Suchance - Huila],"SI") -> 0 | Q14: =+P14/C14 -> 0 | R14: =SUMIFS(disponibilidad[Tiempo falla (en Mintuos)],disponibilidad[Mes],$B14,disponibilidad[[Tipo de afectación ]],"caÍda total",disponibilidad[Responsable Falla],"Aliados o terceros",disponibilidad[Acertemos - Cauca],"SI") -> 0 | S14: =+$R$8/$C$8 -> 0
B15: Agosto | C15: =VLOOKUP(B15,Maestro!$A$7:$D$19,4,FALSE) -> 44640 | D15: =+(($C15-(SUMIFS(disponibilidad[Tiempo falla (en Mintuos)],disponibilidad[JADE],"SI",disponibilidad[Mes],$B15,disponibilidad[[Tipo de afectación ]],"caÍda total",disponibilidad[Responsable Falla],"Matrix Tech",disponibilidad[Suchance - Huila],"SI")))/$C15)*100 -> 100 | E15: =+(($C15-(SUMIFS(disponibilidad[Tiempo falla (en Mintuos)],disponibilidad[SIGA],"SI",disponibilidad[Mes],$B15,disponibilidad[[Tipo de afectación ]],"caÍda total",disponibilidad[Responsable Falla],"Matrix Tech",disponibilidad[Suchance - Huila],"SI")))/$C15)*100 -> 100 | F15: =SUMPRODUCT($D$7:$E$7,D15:E15)/$K$7 -> 100 | G15: =+(($C15-(SUMIFS(disponibilidad[Tiempo falla (en Mintuos)],disponibilidad[Apuestas - Chance],"SI",disponibilidad[Mes],$B15,disponibilidad[[Tipo de afectación ]],"caÍda total",disponibilidad[Responsable Falla],"Matrix Tech",disponibilidad[Suchance - Huila],"SI")))/$C15)*100 -> 100 | H15: =+(($C15-(SUMIFS(disponibilidad[Tiempo falla (en Mintuos)],disponibilidad[PAGOS],"SI",disponibilidad[Mes],$B15,disponibilidad[[Tipo de afectación ]],"caÍda total",disponibilidad[Responsable Falla],"Matrix Tech",disponibilidad[Suchance - Huila],"SI")))/$C15)*100 -> 100 | I15: =+(($C15-(SUMIFS(disponibilidad[Tiempo falla (en Mintuos)],disponibilidad[RECAUDOS],"SI",disponibilidad[Mes],$B15,disponibilidad[[Tipo de afectación ]],"caÍda total",disponibilidad[Responsable Falla],"Matrix Tech",disponibilidad[Suchance - Huila],"SI")))/$C15)*100 -> 100 | J15: =+(($C15-(SUMIFS(disponibilidad[Tiempo falla (en Mintuos)],disponibilidad[RECARGAS],"SI",disponibilidad[Mes],$B15,disponibilidad[[Tipo de afectación ]],"caÍda total",disponibilidad[Responsable Falla],"Matrix Tech",disponibilidad[Suchance - Huila],"SI")))/$C15)*100 -> 100 | K15: =SUMPRODUCT($G$7:$J$7,G15:J15)/$K$7 -> 100 | L15: =+(($C15-(SUMIFS(disponibilidad[Tiempo falla (en Mintuos)],disponibilidad[PAGOS],"SI",disponibilidad[Mes],$B15,disponibilidad[[Tipo de afectación ]],"caÍda total",disponibilidad[Responsable Falla],"Aliados o terceros",disponibilidad[Acertemos - Cauca],"SI")))/$C15)*100 -> 100 | M15: =+(($C15-(SUMIFS(disponibilidad[Tiempo falla (en Mintuos)],disponibilidad[RECAUDOS],"SI",disponibilidad[Mes],$B15,disponibilidad[[Tipo de afectación ]],"caÍda total",disponibilidad[Responsable Falla],"Aliados o terceros",disponibilidad[Acertemos - Cauca],"SI")))/$C15)*100 -> 100 | N15: =+(($C15-(SUMIFS(disponibilidad[Tiempo falla (en Mintuos)],disponibilidad[RECARGAS],"SI",disponibilidad[Mes],$B15,disponibilidad[[Tipo de afectación ]],"caÍda total",disponibilidad[Responsable Falla],"Aliados o terceros",disponibilidad[Acertemos - Cauca],"SI")))/$C15)*100 -> 100 | O15: =AVERAGE(L15:N15) -> 100 | P15: =SUMIFS(disponibilidad[Tiempo falla (en Mintuos)],disponibilidad[Mes],$B15,disponibilidad[[Tipo de afectación ]],"caÍda total",disponibilidad[Responsable Falla],"Matrix Tech",disponibilidad[Suchance - Huila],"SI") -> 0 | Q15: =+P15/C15 -> 0 | R15: =SUMIFS(disponibilidad[Tiempo falla (en Mintuos)],disponibilidad[Mes],$B15,disponibilidad[[Tipo de afectación ]],"caÍda total",disponibilidad[Responsable Falla],"Aliados o terceros",disponibilidad[Acertemos - Cauca],"SI") -> 0 | S15: =+$R$8/$C$8 -> 0 | X15: Apuestas - Chance | Y15: =VLOOKUP($Y$7,$B$8:$R$17,8,FALSE) -> 100
B16: Septiembre | C16: =VLOOKUP(B16,Maestro!$A$7:$D$19,4,FALSE) -> 43200 | D16: =+(($C16-(SUMIFS(disponibilidad[Tiempo falla (en Mintuos)],disponibilidad[JADE],"SI",disponibilidad[Mes],$B16,disponibilidad[[Tipo de afectación ]],"caÍda total",disponibilidad[Responsable Falla],"Matrix Tech",disponibilidad[Suchance - Huila],"SI")))/$C16)*100 -> 100 | E16: =+(($C16-(SUMIFS(disponibilidad[Tiempo falla (en Mintuos)],disponibilidad[SIGA],"SI",disponibilidad[Mes],$B16,disponibilidad[[Tipo de afectación ]],"caÍda total",disponibilidad[Responsable Falla],"Matrix Tech",disponibilidad[Suchance - Huila],"SI")))/$C16)*100 -> 100 | F16: =SUMPRODUCT($D$7:$E$7,D16:E16)/$K$7 -> 100 | G16: =+(($C16-(SUMIFS(disponibilidad[Tiempo falla (en Mintuos)],disponibilidad[Apuestas - Chance],"SI",disponibilidad[Mes],$B16,disponibilidad[[Tipo de afectación ]],"caÍda total",disponibilidad[Responsable Falla],"Matrix Tech",disponibilidad[Suchance - Huila],"SI")))/$C16)*100 -> 100 | H16: =+(($C16-(SUMIFS(disponibilidad[Tiempo falla (en Mintuos)],disponibilidad[PAGOS],"SI",disponibilidad[Mes],$B16,disponibilidad[[Tipo de afectación ]],"caÍda total",disponibilidad[Responsable Falla],"Matrix Tech",disponibilidad[Suchance - Huila],"SI")))/$C16)*100 -> 100 | I16: =+(($C16-(SUMIFS(disponibilidad[Tiempo falla (en Mintuos)],disponibilidad[RECAUDOS],"SI",disponibilidad[Mes],$B16,disponibilidad[[Tipo de afectación ]],"caÍda total",disponibilidad[Responsable Falla],"Matrix Tech",disponibilidad[Suchance - Huila],"SI")))/$C16)*100 -> 100 | J16: =+(($C16-(SUMIFS(disponibilidad[Tiempo falla (en Mintuos)],disponibilidad[RECARGAS],"SI",disponibilidad[Mes],$B16,disponibilidad[[Tipo de afectación ]],"caÍda total",disponibilidad[Responsable Falla],"Matrix Tech",disponibilidad[Suchance - Huila],"SI")))/$C16)*100 -> 100 | K16: =SUMPRODUCT($G$7:$J$7,G16:J16)/$K$7 -> 100 | L16: =+(($C16-(SUMIFS(disponibilidad[Tiempo falla (en Mintuos)],disponibilidad[PAGOS],"SI",disponibilidad[Mes],$B16,disponibilidad[[Tipo de afectación ]],"caÍda total",disponibilidad[Responsable Falla],"Aliados o terceros",disponibilidad[Acertemos - Cauca],"SI")))/$C16)*100 -> 100 | M16: =+(($C16-(SUMIFS(disponibilidad[Tiempo falla (en Mintuos)],disponibilidad[RECAUDOS],"SI",disponibilidad[Mes],$B16,disponibilidad[[Tipo de afectación ]],"caÍda total",disponibilidad[Responsable Falla],"Aliados o terceros",disponibilidad[Acertemos - Cauca],"SI")))/$C16)*100 -> 100 | N16: =+(($C16-(SUMIFS(disponibilidad[Tiempo falla (en Mintuos)],disponibilidad[RECARGAS],"SI",disponibilidad[Mes],$B16,disponibilidad[[Tipo de afectación ]],"caÍda total",disponibilidad[Responsable Falla],"Aliados o terceros",disponibilidad[Acertemos - Cauca],"SI")))/$C16)*100 -> 100 | O16: =AVERAGE(L16:N16) -> 100 | P16: =SUMIFS(disponibilidad[Tiempo falla (en Mintuos)],disponibilidad[Mes],$B16,disponibilidad[[Tipo de afectación ]],"caÍda total",disponibilidad[Responsable Falla],"Matrix Tech",disponibilidad[Suchance - Huila],"SI") -> 0 | Q16: =+P16/C16 -> 0 | R16: =SUMIFS(disponibilidad[Tiempo falla (en Mintuos)],disponibilidad[Mes],$B16,disponibilidad[[Tipo de afectación ]],"caÍda total",disponibilidad[Responsable Falla],"Aliados o terceros",disponibilidad[Acertemos - Cauca],"SI") -> 0 | S16: =+$R$8/$C$8 -> 0 | X16: PAGOS | Y16: =VLOOKUP($Y$7,$B$8:$R$17,9,FALSE) -> 100
B17: Octubre | C17: =VLOOKUP(B17,Maestro!$A$7:$D$19,4,FALSE) -> 44640 | D17: =+(($C17-(SUMIFS(disponibilidad[Tiempo falla (en Mintuos)],disponibilidad[JADE],"SI",disponibilidad[Mes],$B17,disponibilidad[[Tipo de afectación ]],"caÍda total",disponibilidad[Responsable Falla],"Matrix Tech",disponibilidad[Suchance - Huila],"SI")))/$C17)*100 -> 100 | E17: =+(($C17-(SUMIFS(disponibilidad[Tiempo falla (en Mintuos)],disponibilidad[SIGA],"SI",disponibilidad[Mes],$B17,disponibilidad[[Tipo de afectación ]],"caÍda total",disponibilidad[Responsable Falla],"Matrix Tech",disponibilidad[Suchance - Huila],"SI")))/$C17)*100 -> 100 | F17: =SUMPRODUCT($D$7:$E$7,D17:E17)/$K$7 -> 100 | G17: =+(($C17-(SUMIFS(disponibilidad[Tiempo falla (en Mintuos)],disponibilidad[Apuestas - Chance],"SI",disponibilidad[Mes],$B17,disponibilidad[[Tipo de afectación ]],"caÍda total",disponibilidad[Responsable Falla],"Matrix Tech",disponibilidad[Suchance - Huila],"SI")))/$C17)*100 -> 100 | H17: =+(($C17-(SUMIFS(disponibilidad[Tiempo falla (en Mintuos)],disponibilidad[PAGOS],"SI",disponibilidad[Mes],$B17,disponibilidad[[Tipo de afectación ]],"caÍda total",disponibilidad[Responsable Falla],"Matrix Tech",disponibilidad[Suchance - Huila],"SI")))/$C17)*100 -> 100 | I17: =+(($C17-(SUMIFS(disponibilidad[Tiempo falla (en Mintuos)],disponibilidad[RECAUDOS],"SI",disponibilidad[Mes],$B17,disponibilidad[[Tipo de afectación ]],"caÍda total",disponibilidad[Responsable Falla],"Matrix Tech",disponibilidad[Suchance - Huila],"SI")))/$C17)*100 -> 100 | J17: =+(($C17-(SUMIFS(disponibilidad[Tiempo falla (en Mintuos)],disponibilidad[RECARGAS],"SI",disponibilidad[Mes],$B17,disponibilidad[[Tipo de afectación ]],"caÍda total",disponibilidad[Responsable Falla],"Matrix Tech",disponibilidad[Suchance - Huila],"SI")))/$C17)*100 -> 100 | K17: =SUMPRODUCT($G$7:$J$7,G17:J17)/$K$7 -> 100 | L17: =+(($C17-(SUMIFS(disponibilidad[Tiempo falla (en Mintuos)],disponibilidad[PAGOS],"SI",disponibilidad[Mes],$B17,disponibilidad[[Tipo de afectación ]],"caÍda total",disponibilidad[Responsable Falla],"Aliados o terceros",disponibilidad[Acertemos - Cauca],"SI")))/$C17)*100 -> 100 | M17: =+(($C17-(SUMIFS(disponibilidad[Tiempo falla (en Mintuos)],disponibilidad[RECAUDOS],"SI",disponibilidad[Mes],$B17,disponibilidad[[Tipo de afectación ]],"caÍda total",disponibilidad[Responsable Falla],"Aliados o terceros",disponibilidad[Acertemos - Cauca],"SI")))/$C17)*100 -> 100 | N17: =+(($C17-(SUMIFS(disponibilidad[Tiempo falla (en Mintuos)],disponibilidad[RECARGAS],"SI",disponibilidad[Mes],$B17,disponibilidad[[Tipo de afectación ]],"caÍda total",disponibilidad[Responsable Falla],"Aliados o terceros",disponibilidad[Acertemos - Cauca],"SI")))/$C17)*100 -> 100 | O17: =AVERAGE(L17:N17) -> 100 | P17: =SUMIFS(disponibilidad[Tiempo falla (en Mintuos)],disponibilidad[Mes],$B17,disponibilidad[[Tipo de afectación ]],"caÍda total",disponibilidad[Responsable Falla],"Matrix Tech",disponibilidad[Suchance - Huila],"SI") -> 0 | Q17: =+P17/C17 -> 0 | R17: =SUMIFS(disponibilidad[Tiempo falla (en Mintuos)],disponibilidad[Mes],$B17,disponibilidad[[Tipo de afectación ]],"caÍda total",disponibilidad[Responsable Falla],"Aliados o terceros",disponibilidad[Suchance - Huila],"SI") -> 0 | S17: =+$R$8/$C$8 -> 0 | X17: RECAUDOS | Y17: =VLOOKUP($Y$7,$B$8:$R$17,10,FALSE) -> 100
B18: Noviembre | C18: =VLOOKUP(B18,Maestro!$A$7:$D$19,4,FALSE) -> 43200 | D18: =+(($C18-(SUMIFS(disponibilidad[Tiempo falla (en Mintuos)],disponibilidad[JADE],"SI",disponibilidad[Mes],$B18,disponibilidad[[Tipo de afectación ]],"caÍda total",disponibilidad[Responsable Falla],"Matrix Tech",disponibilidad[Suchance - Huila],"SI")))/$C18)*100 -> 100 | E18: =+(($C18-(SUMIFS(disponibilidad[Tiempo falla (en Mintuos)],disponibilidad[SIGA],"SI",disponibilidad[Mes],$B18,disponibilidad[[Tipo de afectación ]],"caÍda total",disponibilidad[Responsable Falla],"Matrix Tech",disponibilidad[Suchance - Huila],"SI")))/$C18)*100 -> 100 | F18: =SUMPRODUCT($D$7:$E$7,D18:E18)/$K$7 -> 100 | G18: =+(($C18-(SUMIFS(disponibilidad[Tiempo falla (en Mintuos)],disponibilidad[Apuestas - Chance],"SI",disponibilidad[Mes],$B18,disponibilidad[[Tipo de afectación ]],"caÍda total",disponibilidad[Responsable Falla],"Matrix Tech",disponibilidad[Suchance - Huila],"SI")))/$C18)*100 -> 100 | H18: =+(($C18-(SUMIFS(disponibilidad[Tiempo falla (en Mintuos)],disponibilidad[PAGOS],"SI",disponibilidad[Mes],$B18,disponibilidad[[Tipo de afectación ]],"caÍda total",disponibilidad[Responsable Falla],"Matrix Tech",disponibilidad[Suchance - Huila],"SI")))/$C18)*100 -> 100 | I18: =+(($C18-(SUMIFS(disponibilidad[Tiempo falla (en Mintuos)],disponibilidad[RECAUDOS],"SI",disponibilidad[Mes],$B18,disponibilidad[[Tipo de afectación ]],"caÍda total",disponibilidad[Responsable Falla],"Matrix Tech",disponibilidad[Suchance - Huila],"SI")))/$C18)*100 -> 100 | J18: =+(($C18-(SUMIFS(disponibilidad[Tiempo falla (en Mintuos)],disponibilidad[RECARGAS],"SI",disponibilidad[Mes],$B18,disponibilidad[[Tipo de afectación ]],"caÍda total",disponibilidad[Responsable Falla],"Matrix Tech",disponibilidad[Suchance - Huila],"SI")))/$C18)*100 -> 100 | K18: =SUMPRODUCT($G$7:$J$7,G18:J18)/$K$7 -> 100 | L18: =+(($C18-(SUMIFS(disponibilidad[Tiempo falla (en Mintuos)],disponibilidad[PAGOS],"SI",disponibilidad[Mes],$B18,disponibilidad[[Tipo de afectación ]],"caÍda total",disponibilidad[Responsable Falla],"Aliados o terceros",disponibilidad[Acertemos - Cauca],"SI")))/$C18)*100 -> 100 | M18: =+(($C18-(SUMIFS(disponibilidad[Tiempo falla (en Mintuos)],disponibilidad[RECAUDOS],"SI",disponibilidad[Mes],$B18,disponibilidad[[Tipo de afectación ]],"caÍda total",disponibilidad[Responsable Falla],"Aliados o terceros",disponibilidad[Acertemos - Cauca],"SI")))/$C18)*100 -> 100 | N18: =+(($C18-(SUMIFS(disponibilidad[Tiempo falla (en Mintuos)],disponibilidad[RECARGAS],"SI",disponibilidad[Mes],$B18,disponibilidad[[Tipo de afectación ]],"caÍda total",disponibilidad[Responsable Falla],"Aliados o terceros",disponibilidad[Acertemos - Cauca],"SI")))/$C18)*100 -> 100 | O18: =AVERAGE(L18:N18) -> 100 | P18: =SUMIFS(disponibilidad[Tiempo falla (en Mintuos)],disponibilidad[Mes],$B18,disponibilidad[[Tipo de afectación ]],"caÍda total",disponibilidad[Responsable Falla],"Matrix Tech",disponibilidad[Suchance - Huila],"SI") -> 0 | Q18: =+P18/C18 -> 0 | R18: =SUMIFS(disponibilidad[Tiempo falla (en Mintuos)],disponibilidad[Mes],$B18,disponibilidad[[Tipo de afectación ]],"caÍda total",disponibilidad[Responsable Falla],"Aliados o terceros",disponibilidad[Suchance - Huila],"SI") -> 0 | S18: =+$R$8/$C$8 -> 0 | X18: RECARGAS | Y18: =VLOOKUP($Y$7,$B$8:$R$17,11,FALSE) -> 100
